<mujoco model="fruitfly">
  <compiler autolimits="true" angle="radian" />
  <option gravity="0 0 -981" density="0.00128" viscosity="0.000185" cone="elliptic" noslip_iterations="3" />
  <size njmax="300" nconmax="100" nkey="1" />
  <default>
    <mesh scale="0.1 0.1 0.1" />
    <geom friction="0.5" solref="0.0002 1" solimp="0.95 0.99 0.01" />
    <general ctrllimited="true" />
    <default class="body">
      <joint limited="true" solreflimit="0.001 1" armature="1e-02" />
      <geom type="mesh" contype="0" conaffinity="0" group="1" material="body" density="0.478" />
      <site group="3" size="0.01" />
      <default class="collision">
        <geom type="capsule" contype="1" conaffinity="1" condim="1" group="4" material="blue" density="0" />
        <default class="adhesion-collision">
          <geom material="pink" friction="0.6" margin="0.0005" gap="0.0005" />
          <site type="capsule" />
        </default>
        <default class="collision-membrane">
          <geom group="5" />
        </default>
      </default>
      <default class="adhesion">
        <general dyntype="none" dynprm="1" />
        <default class="adhesion_claw">
          <adhesion group="3" ctrlrange="0 1" gain="0.985" />
        </default>
        <default class="adhesion_labrum">
          <adhesion group="3" ctrlrange="0 1" gain="1" />
        </default>
      </default>
      <default class="head">
        <joint stiffness="0.03" damping="0.001" />
        <geom density="0.575" />
        <general forcerange="-0.1 0.1" gainprm="0.1" />
        <default class="labrum">
          <general forcerange="-0.01 0.01" gainprm="0.01" />
        </default>
      </default>
      <default class="antenna">
        <joint damping="0.0003" />
        <general forcerange="-0.01 0.01" gainprm="0.01" />
        <default class="antenna_extend">
          <joint axis="1 0 0" range="-0.2 0.5" />
        </default>
        <default class="antenna_twist">
          <joint axis="0 1 0" range="-0.1 0.09" />
        </default>
        <default class="antenna_abduct">
          <joint axis="0 0 1" range="-0.4 0.8" />
        </default>
      </default>
      <default class="wing">
        <joint stiffness="0.01" damping="0.0005" />
        <general ctrlrange="-.55 .55" />
        <default class="yaw">
          <joint axis="0 0 1" range="-1.5 1.5" springref="1.5" />
          <general gainprm="3" />
        </default>
        <default class="roll">
          <joint axis="1 0 0" range="-1 1.5" springref="0.7" />
          <general gainprm="2" />
        </default>
        <default class="pitch">
          <joint axis="0 1 0" range="-1.27 2.92" springref="-1" />
          <general gainprm="1" />
        </default>
        <default class="wing-inertial">
          <geom type="box" rgba="0 0 0 0" mass="8e-06" />
        </default>
        <default class="wing-fluid">
          <geom type="ellipsoid" group="3" mass="0" />
        </default>
      </default>
      <default class="abdomen">
        <joint group="3" stiffness="0.05" damping="0.01" />
        <geom density="0.445" />
        <general gainprm="0.1" />
        <default class="abduct_abdomen">
          <joint axis="0 0 1" range="-0.1 0.1" />
        </default>
        <default class="extend_abdomen">
          <joint axis="1 0 0" range="-0.15 0.1" />
        </default>
      </default>
      <default class="haltere">
        <joint axis="1 0 0" springdamper="0.005 0.1" range="-0.2 0.2" />
      </default>
      <default class="leg">
        <joint stiffness="0.01" />
        <geom density="1.21" />
        <default class="coxa">
          <default class="twist_coxa_T1">
            <joint axis="0 1 0" range="-0.8 0.8" />
            <general ctrlrange="-10 10" ctrllimited="true" />
          </default>
          <default class="flexion_coxa_T1">
            <joint axis="0 0 1" range="-1 0.7" />
            <general ctrlrange="-10 10" ctrllimited="true" />
          </default>
          <default class="extend_coxa_T1">
            <joint axis="1 0 0" range="-0.2 1.7" />
            <general ctrlrange="-10 10" ctrllimited="true" />
          </default>
          <default class="twist_coxa_T2">
            <joint axis="0 1 0" range="-0.75 0.8" />
            <general ctrlrange="-10 10" ctrllimited="true" />
          </default>
          <default class="flexion_coxa_T2">
            <joint axis="0 0 1" range="-0.5 0.3" />
            <general ctrlrange="-10 10" ctrllimited="true" />
          </default>
          <default class="extend_coxa_T2">
            <joint axis="1 0 0" range="-0.2 0.9" />
            <general ctrlrange="-10 10" ctrllimited="true" />
          </default>
          <default class="twist_coxa_T3">
            <joint axis="0 1 0" range="-0.15 0.8" />
            <general ctrlrange="-10 10" ctrllimited="true" />
          </default>
          <default class="flexion_coxa_T3">
            <joint axis="0 0 1" range="-0.9 0.25" />
            <general ctrlrange="-10 10" ctrllimited="true" />
          </default>
          <default class="extend_coxa_T3">
            <joint axis="1 0 0" range="-0.3 1.3" />
            <general ctrlrange="-10 10" ctrllimited="true" />
          </default>
        </default>
        <default class="femur">
          <default class="twist_femur">
            <joint axis="0 1 0" range="-1 1" />
            <general ctrlrange="-10 10" ctrllimited="true" />
            <default class="twist_femur_T2">
              <general ctrlrange="-10 10" ctrllimited="true" />
            </default>
            <default class="twist_femur_T3">
              <general ctrlrange="-10 10" ctrllimited="true" />
            </default>
          </default>
          <default class="extend_femur">
            <joint axis="1 0 0" range="-0.15 2" />
            <default class="extend_femur_T1">
              <general ctrlrange="-10 10" ctrllimited="true" />
            </default>
            <default class="extend_femur_T2">
              <general ctrlrange="-10 10" ctrllimited="true" />
            </default>
          </default>
          <default class="extend_femur_T3">
            <joint axis="1 0 0" range="-0.7 1.5" />
            <general ctrlrange="-10 10" ctrllimited="true" />
          </default>
        </default>
        <default class="tibia">
          <default class="extend_tibia">
            <joint axis="1 0 0" range="-1.35 1.3" />
            <general ctrlrange="-10 10" ctrllimited="true" />
            <default class="extend_tibia_T2">
              <general ctrlrange="-10 10" ctrllimited="true" />
            </default>
            <default class="extend_tibia_T3">
              <general ctrlrange="-10 10" ctrllimited="true" />
            </default>
          </default>
        </default>
        <default class="tarsus">
          <joint axis="1 0 0" />
          <default class="extend_tarsus_T1">
            <joint range="-0.7 1.2" />
            <general ctrlrange="-10 10" ctrllimited="true" />
          </default>
          <default class="extend_tarsus_T2">
            <joint range="-1 1.8" />
            <general ctrlrange="-10 10" ctrllimited="true" />
          </default>
          <default class="extend_tarsus_T3">
            <joint range="-0.8 1.2" />
            <general ctrlrange="-10 10" ctrllimited="true" />
          </default>
          <default class="extend_tarsus">
            <joint group="3" stiffness="0.1" range="-0.36 0.36" />
            <general ctrlrange="-10 10" ctrllimited="true" />
          </default>
        </default>
      </default>
    </default>
  </default>
  <visual>
    <global offwidth="3840" offheight="2160" />
    <quality shadowsize="2048" offsamples="24" />
    <headlight ambient="0.4 0.4 0.4" diffuse="0.8 0.8 0.8" specular="0.1 0.1 0.1" />
    <map stiffness="1e+04" stiffnessrot="5e+04" force="2e-05" />
    <scale jointwidth="0.01" framewidth="0.01" />
  </visual>
  <statistic meansize="0.02" />
  <asset>
    <texture name="grid" type="2d" builtin="checker" rgb1=".1 .2 .3" rgb2=".2 .3 .4" width="300" height="300" mark="edge" markrgb=".2 .3 .4" />
    <material name="grid" texture="grid" texrepeat="1 1" texuniform="true" reflectance=".2" />
    <texture type="2d" name="groundplane" builtin="checker" rgb1="0.2 0.3 0.4" rgb2="0.1 0.2 0.3" width="200" height="200" />
    <material name="body" shininess="0.6" rgba="0.674 0.35 0.143 1" />
    <material name="red" shininess="0.692" rgba="0.8 0.0279 0.00154 1" />
    <material name="ocelli" shininess="1" rgba="0.128 0.0488 0.0154 1" />
    <material name="black" shininess="0.727" rgba="0 0 0 1" />
    <material name="bristle-brown" shininess="0.907" rgba="0 0 0 1" />
    <material name="lower" shininess="0.6" rgba="0.799 0.61 0.386 1" />
    <material name="brown" shininess="0.6" rgba="0.202 0.0782 0.0262 1" />
    <material name="membrane" specular="0.62" shininess="0.907" rgba="0.539 0.686 0.8 0.4" />
    <material name="blue" shininess="0.6" rgba="0.2 0.3 1 1" />
    <material name="ballsurface" texture="groundplane" texuniform="true" texrepeat="2 2" reflectance="0.2" />
    <material name="pink" rgba="0.6 0.3 1 1" />
  </asset>
  <worldbody>
    <body name="thorax" childclass="body">
      <light name="right" mode="trackcom" pos="0 -1 1" dir="0 1 -1" diffuse="0.3 0.3 0.3" />
      <camera name="track1" mode="trackcom" pos="0.6 0.6 0.22" quat="0.312 0.221 0.533 0.754" />
      <camera name="track2" mode="trackcom" pos="0 -1.1 0.1" quat="0.707 0.707 0 0" />
      <camera name="track3" mode="trackcom" pos="-0.9 -0.9 0.9" quat="0.82 0.425 -0.176 -0.34" />
      <camera name="back" mode="track" pos="-0.462 0 0.297" xyaxes="0 -1 0 0.707 0 0.707" />
      <camera name="side" mode="track" pos="-0.055 0.424 -0.064" xyaxes="-1 0 0 0 0 1" />
      <camera name="bottom" mode="track" pos="0.01 0 -0.516" xyaxes="0 1 0 0.991 0 0.136" />
      <light name="left" mode="trackcom" pos="0 1 1" dir="0 -1 -1" diffuse="0.3 0.3 0.3" />
      <light name="tracking" mode="trackcom" pos="0 0 1" />
      <site name="thorax_site" />
      <site name="hover_up_dir" pos="0.0262 0 0.0262" quat="0.915 0 0.403 0" />
      <geom name="thorax" mass="0.00034" pos="-0.00416991 3.8147e-07 0.0046216" type="sphere" size="0.0526589" />
      <geom name="thorax_collision" class="collision" type="ellipsoid" size="0.0437 0.0437 0.0551" pos="0.00168 0 -0.00262" quat="0 -0.479 0 -0.878" />
      <geom name="thorax_collision2" class="collision" type="ellipsoid" size="0.0499 0.028 0.0114" pos="-0.00445 0 0.0219" quat="0 -0.199 0 -0.98" />
      <geom name="thorax_black" material="black" mass="0" pos="-0.0238946 -0.000445322 0.0183603" type="sphere" size="0.0530646" />
      <body name="head" childclass="head" pos="0.0567 3.81e-07 -0.00305" quat="0.702 -0.087 0.087 -0.702">
        <site name="head_site" pos="0 0.015 0" quat="0 0 0 1" />
        <geom name="head_collision" class="collision" type="ellipsoid" size="0.0455 0.0262 0.0324" pos="0 0.0149 0.000875" euler="0.3 0 0" />
        <geom name="head" pos="3.40006e-08 0.0196711 0.00157814" type="sphere" size="0.0322604" />
        <geom name="head_red" material="red" pos="3.40006e-08 0.0178867 0.00340486" type="capsule" size="0.0259542 0.0193202" quat="0.401538 0.582037 -0.401538 -0.582037" />
        <geom name="head_ocelli" material="ocelli" pos="-1.1812e-05 0.0192126 0.0317863" type="capsule" size="0.00299767 0.00237788" quat="0.557699 -0.434709 0.557699 -0.434709" />
        <camera name="eye_right" fovy="140" pos="0.0219 0.0131 0" quat="0.474 0.688 -0.344 -0.429" />
        <camera name="eye_left" fovy="140" pos="-0.0219 0.0131 0" quat="0.474 0.688 0.344 0.429" />
        <geom name="head_black" material="black" mass="0" pos="-0.000956352 0.0164357 0.00955916" type="sphere" size="0.0439881" />
        <body name="rostrum" pos="0 0.0368 -0.0235" quat="2.2e-07 -1.21e-07 0.192 -0.981">
          <geom name="rostrum" pos="-2.00204e-08 0.0188873 -0.00389886" type="sphere" size="0.0216166" />
          <geom name="rostrum_collision_right" class="collision" size="0.0035" fromto="0.00613 0.0324 0 0.0114 0.0245 -0.0236" />
          <geom name="rostrum_collision_left" class="collision" size="0.0035" fromto="-0.00613 0.0324 0 -0.0114 0.0245 -0.0236" />
          <geom name="rostrum_collision" class="collision" type="ellipsoid" size="0.0131 0.0219 0.0131" pos="0 0.0175 0.00263" euler="0.1 0 0" />
          <geom name="rostrum_bristle-brown" material="bristle-brown" pos="-1.92753e-08 0.0237805 -0.0252153" type="capsule" size="0.00642836 0.011294" quat="0.463827 0.533727 0.463827 0.533727" />
          <body name="haustellum" pos="0 0.0377 0" quat="2.33e-07 -1.56e-07 -0.347 0.938">
            <geom name="haustellum" pos="4.66281e-08 0.0122925 -0.00107128" type="capsule" size="0.00908976 0.00490103" quat="0.632956 0.774188 0 0" />
            <geom name="haustellum_collision" class="collision" type="capsule" size="0.00788 0.00788" pos="0 0.0123 -0.000948" quat="0.633 0.774 0 0" />
            <geom name="haustellum_black" material="black" mass="0" pos="9.39109e-05 0.0141229 -0.00269677" type="capsule" size="0.00953929 0.00374094" quat="0.340035 0.619981 -0.340035 -0.619981" />
            <body name="labrum_left" childclass="labrum" pos="-0.00263 0.0182 0" quat="0.741 -0.0142 -0.591 0.319">
              <geom name="labrum_left_lower" material="lower" pos="-0.000802061 0.0083688 -0.00346569" type="sphere" size="0.0102514" />
              <geom name="labrum_left_lower_collision" class="adhesion-collision" type="ellipsoid" size="0.0035 0.00875 0.0131" pos="-0.000603 0.0106 -0.00438" quat="-0.174 -0.715 0.0876 0.672" />
            </body>
            <body name="labrum_right" childclass="labrum" pos="0.00263 0.0182 0" quat="0.699 0.00274 0.642 -0.316">
              <geom name="labrum_right_lower" material="lower" pos="0.00111101 0.00854922 -0.00331572" type="sphere" size="0.0102514" />
              <geom name="labrum_right_lower_collision" class="adhesion-collision" type="ellipsoid" size="0.0035 0.00875 0.0131" pos="0.00116 0.0106 -0.00414" quat="-0.175 -0.668 -0.0724 -0.719" />
            </body>
          </body>
        </body>
        <body name="antenna_left" pos="-0.00795 0.0378 0.0129" quat="0.785 -0.59 -0.0128 0.192">
          <geom name="antenna_left" pos="-0.0127332 0.0172294 0.00276934" type="ellipsoid" size="0.00540057 0.0168397 0.0238518" quat="-0.191167 0.618154 -0.382605 -0.659511" />
          <geom name="antenna_left_collision" class="collision" type="capsule" size="0.00481 0.00875" pos="0 0.0114 0.00263" quat="0.634 -0.773 0 0" />
          <geom name="antenna_left_black" material="black" mass="0" pos="-0.00108258 0.00432222 0.00683451" type="sphere" size="0.00538933" />
        </body>
        <body name="antenna_right" pos="0.00861 0.038 0.0129" quat="0.59 0.785 -0.192 -0.0128">
          <geom name="antenna_right" pos="0.0122325 -0.0172292 -0.00276918" type="ellipsoid" size="0.0054006 0.0168397 0.0238519" quat="-0.65951 0.382606 0.618154 0.191168" />
          <geom name="antenna_right_collision" class="collision" type="capsule" size="0.00481 0.00875" pos="-0.000616 -0.0114 -0.00231" quat="0.782 0.623 -0.0258 -0.0164" />
          <geom name="antenna_right_black" material="black" mass="0" pos="0.000581903 -0.00432197 -0.00683437" type="sphere" size="0.00538934" />
        </body>
      </body>
      <body name="wing_left" childclass="wing" pos="-0.00694 0.0432 0.0091" quat="0.617    -0.402    -0.304    -0.604">
        <geom name="wing_left_brown" material="brown" mass="0" pos="0.0243478 -0.128904 -0.0265263" type="ellipsoid" size="0.00312095 0.0525679 0.133699" quat="-0.656571 -0.663353 0.253573 -0.254121" />
        <geom name="wing_left_brown_collision" class="collision" type="ellipsoid" size="0.00219 0.0175 0.114" pos="0.00186 -0.11 -0.00166" quat="-0.673 -0.647 0.26 -0.248" />
        <geom name="wing_left_membrane" material="membrane" mass="0" pos="0.0266037 -0.132028 -0.0290936" type="ellipsoid" size="0.000174289 0.0554888 0.130025" quat="-0.649138 -0.670539 0.250921 -0.256976" />
        <geom name="wing_left_membrane_collision" class="collision-membrane" type="ellipsoid" size="0.00306 0.0551 0.114" pos="0.0263 -0.148 -0.0289" quat="-0.685 -0.634 0.265 -0.243" />
        <geom name="wing_left_fluid" class="wing-fluid" size="0.0005 0.0551 0.114" pos="0.0263 -0.148 -0.0289" quat="-0.685 -0.634 0.265 -0.243" />
        <geom name="wing_left_inertial" class="wing-inertial" size="0.0005 0.0551 0.114" pos="0.0263 -0.148 -0.0289" quat="-0.685 -0.634 0.265 -0.243" />
      </body>
      <body name="wing_right" childclass="wing" pos="-0.00694 -0.0432 0.0091" quat="-0.304     0.604    -0.617    -0.402 ">
        <geom name="wing_right_brown" material="brown" mass="0" pos="-0.0243472 0.128903 0.0265271" type="ellipsoid" size="0.00312096 0.0525678 0.133699" quat="0.25411 0.253564 0.663354 -0.656578" />
        <geom name="wing_right_brown_collision" class="collision" type="ellipsoid" size="0.00219 0.0175 0.114" pos="-0.00186 0.11 0.00166" quat="0.248 0.26 0.647 -0.673" />
        <geom name="wing_right_membrane" material="membrane" mass="0" pos="-0.0266031 0.132027 0.0290942" type="ellipsoid" size="0.000174286 0.0554888 0.130025" quat="0.256968 0.250913 0.670542 -0.649141" />
        <geom name="wing_right_membrane_collision" class="collision-membrane" type="ellipsoid" size="0.00306 0.0551 0.114" pos="-0.0263 0.148 0.0289" quat="0.243 0.265 0.634 -0.685" />
        <geom name="wing_right_fluid" class="wing-fluid" size="0.0005 0.0551 0.114" pos="-0.0263 0.148 0.0289" quat="0.243 0.265 0.634 -0.685" />
        <geom name="wing_right_inertial" class="wing-inertial" size="0.0005 0.0551 0.114" pos="-0.0263 0.148 0.0289" quat="0.243 0.265 0.634 -0.685" />
      </body>
      <body name="abdomen" childclass="abdomen" pos="-0.0447 -0.000555 0.00428" quat="-0.704 -0.0859 -0.0853 -0.7">
        <geom name="abdomen" pos="-6.51608e-05 0.0029425 -0.012634" type="ellipsoid" size="0.00970442 0.0303679 0.0327778" quat="0.587787 0.38944 0.581575 0.405727" />
        <geom name="abdomen_lower" material="lower" pos="-0.000338511 -0.00113727 -0.0331854" type="capsule" size="0.0105244 0.0153999" quat="0.538679 0.454951 0.542017 0.457233" />
        <geom name="abdomen_collision" class="collision" type="cylinder" size="0.0281 0.0102 0" pos="-0.000187 0.00646 -0.0146" quat="0.0104 -0.0205 0.824 0.566" />
        <body name="abdomen_2" pos="0 0.0119 0" quat="0.981 -0.192 -0.000269 0.00144">
          <geom name="abdomen_2" pos="-0.000569904 0.0151522 -0.0216331" type="ellipsoid" size="0.0183528 0.041455 0.0415075" quat="0.480713 0.518568 0.47576 0.52312" />
          <geom name="abdomen_2_lower" material="lower" pos="0.000506006 0.0169168 -0.0423167" type="capsule" size="0.0219737 0.0100268" quat="0.274881 0.650786 0.285815 0.647478" />
          <geom name="abdomen_2_collision" class="collision" type="cylinder" size="0.035 0.0142 0" pos="-0.000182 0.0166 -0.015" quat="-0.0458 -0.0256 0.694 0.718" />
          <body name="abdomen_3" pos="0 0.0212 0" quat="0.996 -0.0909 6.69e-05 0.000525">
            <geom name="abdomen_3" pos="0.000114405 0.0211676 -0.0214114" type="sphere" size="0.0422489" />
            <geom name="abdomen_3_lower" material="lower" pos="0.000551221 0.022426 -0.0453978" type="capsule" size="0.0221697 0.0113192" quat="0.128107 0.694435 0.131295 0.695781" />
            <geom name="abdomen_3_collision" class="collision" type="cylinder" size="0.0371 0.0194 0" pos="3.29e-05 0.0198 -0.0136" quat="0.697 -0.605 0.274 0.271" />
            <body name="abdomen_4" pos="0 0.0313 0" quat="0.999 -0.0332 0.000147 -0.000229">
              <geom name="abdomen_4" pos="0.000414169 0.0166373 -0.0197631" type="ellipsoid" size="0.0206209 0.0439879 0.0415087" quat="0.436858 0.549622 0.436698 0.562464" />
              <geom name="abdomen_4_lower" material="lower" pos="0.000508993 0.0196814 -0.046953" type="capsule" size="0.0204552 0.0135975" quat="0.191225 0.679086 0.191684 0.682299" />
              <geom name="abdomen_4_collision" class="collision" type="cylinder" size="0.0377 0.0176 0" pos="9.67e-05 0.015 -0.0158" quat="-0.0133 -0.062 0.637 0.768" />
              <body name="abdomen_5" pos="0 0.0262 0" quat="0.999 -0.0368 -4.72e-05 -0.000327">
                <geom name="abdomen_5" pos="0.000492611 0.0129724 -0.0169182" type="ellipsoid" size="0.0184518 0.0394784 0.0402031" quat="0.433272 0.559456 0.426469 0.563391" />
                <geom name="abdomen_5_lower" material="lower" pos="0.000479531 0.0154536 -0.0433966" type="capsule" size="0.018756 0.0165597" quat="-0.405757 0.580122 -0.403897 0.579385" />
                <geom name="abdomen_5_collision" class="collision" type="cylinder" size="0.0353 0.016 0" pos="0.000282 0.0105 -0.0156" quat="-0.00496 -0.0596 0.624 0.779" />
                <body name="abdomen_6" pos="0 0.0213 0" quat="0.998 -0.0662 0.000156 -0.000351">
                  <geom name="abdomen_6" pos="2.53447e-05 0.0120278 -0.016716" type="sphere" size="0.0319812" />
                  <geom name="abdomen_6_lower" material="lower" pos="6.46424e-05 0.0150611 -0.0365175" type="capsule" size="0.0171362 0.014255" quat="-0.408916 0.578592 -0.406596 0.576799" />
                  <geom name="abdomen_6_collision" class="collision" type="cylinder" size="0.0318 0.0141 0" pos="-0.000157 0.00942 -0.0143" quat="-0.00411 0.000397 0.592 0.806" />
                  <body name="abdomen_7" pos="0 0.0182 0" quat="0.995 -0.102 -1.79e-06 -0.000187">
                    <geom name="abdomen_8" pos="-8.52224e-05 0.0248244 -0.00930379" type="sphere" size="0.021563" />
                    <geom name="abdomen_7" pos="0.000258939 0.00925098 -0.0162839" type="sphere" size="0.0271919" />
                    <geom name="abdomen_7_lower" material="lower" pos="9.75036e-05 0.0137549 -0.0292241" type="capsule" size="0.017067 0.00547658" quat="-0.406201 0.58057 -0.402287 0.579745" />
                  </body>
                </body>
              </body>
            </body>
          </body>
        </body>
      </body>
      <body name="haltere_left" childclass="haltere" pos="-0.0386 0.0247 -0.00866" quat="0.291 -0.204 0.826 0.439">
        <geom name="haltere_left" pos="0.000759072 0.0144939 0.000921985" type="capsule" size="0.00732178 0.00785458" quat="-0.670857 0.700621 -0.160982 -0.182114" />
      </body>
      <body name="haltere_right" childclass="haltere" pos="-0.0386 -0.0247 -0.00866" quat="-0.438 -0.829 0.206 -0.28">
        <geom name="haltere_right" pos="-0.000735649 0.0148176 0.00102949" type="capsule" size="0.00732644 0.00784002" quat="0.161071 -0.144516 0.707528 0.672737" />
      </body>
      <body name="coxa_T1_left" childclass="leg" pos="0.0317 0.0209 -0.0272" quat="-0.532 0.787 -0.311 -0.0229">
        <joint name="coxa_flexion_T1_left" class="flexion_coxa_T1" />
        <joint name="coxa_twist_T1_left" class="twist_coxa_T1" />
        <geom name="coxa_T1_left" pos="-0.000324803 0.0228864 0.000668814" type="capsule" size="0.00787721 0.016155" quat="-0.41761 -0.383358 -0.53138 0.629503" />
        <geom name="coxa_T1_left_collision" class="collision" type="ellipsoid" size="0.00679 0.00752 0.0208" pos="-2.04e-05 0.0261 -0.000454" quat="-0.417 -0.383 -0.532 0.63" />
        <site name="tracking[coxa_T1_left]" pos="0 0 0" size="0.005" group="0" rgba="0 1 0 1" />
        <body name="femur_T1_left" pos="0 0.0437 0" quat="0 0 0.252 0.968">
          <joint name="femur_twist_T1_left" class="twist_femur" />
          <joint name="femur_T1_left" class="extend_femur_T1" />
          <geom name="femur_T1_left" pos="0.00224676 0.0340335 0.00302449" type="capsule" size="0.00728177 0.0304885" quat="0.666666 -0.676013 0.226023 0.217892" />
          <geom name="femur_T1_left_collision" class="collision" size="0.005" fromto="0.00263 0.00263 0.00438 0 0.0662 0" />
          <site name="tracking[femur_T1_left]" pos="0 0 0" size="0.005" group="0" rgba="0 1 0 1" />
          <body name="tibia_T1_left" pos="0 0.0697 0" quat="0.186 0.162 0.677 -0.694">
            <joint name="tibia_T1_left" class="extend_tibia" />
            <geom name="tibia_T1_left" pos="-0.000613914 -0.0268236 -8.63539e-05" type="capsule" size="0.00419274 0.0222342" quat="-0.297997 0.303125 0.660506 0.618906" />
            <geom name="tibia_T1_left_collision" class="collision" size="0.00362" fromto="0 0 0 0 -0.051 0.00175" />
            <site name="tracking[tibia_T1_left]" pos="0 0 0" size="0.005" group="0" rgba="0 1 0 1" />
            <body name="tarsus_T1_left" pos="0 -0.051 0.00175" quat="0.039 0.998 0.00674 0.0474">
              <joint name="tarsus_T1_left" class="extend_tarsus_T1" />
              <geom name="tarsus_T1_left" pos="-0.000558231 0.0120928 0.000950103" type="capsule" size="0.00224226 0.0102124" quat="-0.321106 -0.339421 -0.62503 0.625317" />
              <geom name="tarsus_T1_left_collision" class="collision" size="0.00204" fromto="0 0 0 -0.000165 0.0235 0.00174" />
              <site name="tracking[tarsus_T1_left]" pos="0 0 0" size="0.005" group="0" rgba="0 1 0 1" />
              <body name="tarsus2_T1_left" pos="-0.000165 0.0235 0.00174">
                <geom name="tarsus2_T1_left" pos="-0.000179534 0.00750416 -0.00025319" type="capsule" size="0.00394099 0.00372312" quat="0.373037 0.231023 0.468046 -0.767076" />
                <geom name="tarsus2_T1_left_collision" class="collision" size="0.00159" fromto="0 0 0 0.000113 0.0136 0.000556" />
                <body name="tarsus3_T1_left" pos="0.000113 0.0136 0.000556">
                  <geom name="tarsus3_T1_left" pos="-0.000321019 0.00530192 -0.000800795" type="capsule" size="0.00272893 0.00286279" quat="-0.373037 -0.231023 -0.468046 0.767076" />
                  <geom name="tarsus3_T1_left_collision" class="collision" size="0.00149" fromto="0 0 0 -0.000255 0.00909 0.0002" />
                  <body name="tarsus4_T1_left" pos="-0.000255 0.00909 0.0002">
                    <geom name="tarsus4_T1_left" pos="-0.000312252 0.00457831 -0.000743256" type="capsule" size="0.0020973 0.0026698" quat="0.373037 0.231023 0.468046 -0.767076" />
                    <geom name="tarsus4_T1_left_collision" class="collision" size="0.00148" fromto="0 0 0 -7.12e-05 0.00906 -0.00081" />
                    <body name="claw_T1_left" pos="-7.12e-05 0.00906 -0.00081">
                      <geom name="tarsal_claw_T1_left" material="brown" pos="-0.00119458 0.00574181 0.000681628" type="capsule" size="0.00395499 0.00245772" quat="-0.373037 -0.231023 -0.468046 0.767076" />
                      <geom name="tarsal_claw_T1_left_collision" class="adhesion-collision" type="capsule" size="0.00199" fromto="0 0 0 -7.12e-05 0.00906 -0.00081" />
                      <site name="claw_T1_left" class="adhesion-collision" size="0.00219" fromto="0 0 0 -7.12e-05 0.00906 -0.00081" />
                      <site name="tracking[claw_T1_left]" pos="0 0.005 0" size="0.005" group="0" rgba="0 1 0 1" />
                    </body>
                  </body>
                </body>
              </body>
            </body>
          </body>
        </body>
      </body>
      <body name="coxa_T1_right" childclass="leg" pos="0.0317 -0.0209 -0.0272" quat="0.319 0.011 -0.543 -0.777">
        <joint name="coxa_flexion_T1_right" class="flexion_coxa_T1" />
        <joint name="coxa_twist_T1_right" class="twist_coxa_T1" />
        <geom name="coxa_T1_right" pos="0.00105469 -0.0231929 0.000273755" type="capsule" size="0.00787722 0.016155" quat="-0.507459 0.628009 0.446869 0.385225" />
        <geom name="coxa_T1_right_collision" class="collision" type="ellipsoid" size="0.00679 0.00752 0.0208" pos="0.00061 -0.026 0.00153" quat="-0.508 0.628 0.447 0.385" />
        <site name="tracking[coxa_T1_right]" pos="0 0 0" size="0.005" group="0" rgba="0 1 0 1" />
        <body name="femur_T1_right" pos="0 -0.0436 0" quat="0 0 0.261 0.965">
          <joint name="femur_twist_T1_right" class="twist_femur" />
          <joint name="femur_T1_right" class="extend_femur_T1" />
          <geom name="femur_T1_right" pos="-0.00230382 -0.0339572 -0.00290191" type="capsule" size="0.0072737 0.0304967" quat="0.231721 -0.23911 -0.67152 -0.661961" />
          <geom name="femur_T1_right_collision" class="collision" size="0.005" fromto="-0.00263 -0.00263 -0.00438 0 -0.0663 0" />
          <site name="tracking[femur_T1_right]" pos="0 0 0" size="0.005" group="0" rgba="0 1 0 1" />
          <body name="tibia_T1_right" pos="0 -0.0698 0" quat="0.163 0.148 0.688 -0.692">
            <joint name="tibia_T1_right" class="extend_tibia" />
            <geom name="tibia_T1_right" pos="1.70469e-05 0.0265693 -0.000187745" type="capsule" size="0.00421148 0.0222152" quat="-0.666105 -0.611164 -0.299741 0.304858" />
            <geom name="tibia_T1_right_collision" class="collision" size="0.00362" fromto="0 0 0 0 0.0515 -0.00175" />
            <site name="tracking[tibia_T1_right]" pos="0 0 0" size="0.005" group="0" rgba="0 1 0 1" />
            <body name="tarsus_T1_right" pos="0 0.0515 -0.00175" quat="-0.0745 -0.995 0.0133 0.0704">
              <joint name="tarsus_T1_right" class="extend_tarsus_T1" />
              <geom name="tarsus_T1_right" pos="-0.00015324 -0.0114806 -0.000492614" type="capsule" size="0.002247 0.0102077" quat="-0.674549 0.644256 0.235119 0.273199" />
              <geom name="tarsus_T1_right_collision" class="collision" size="0.00204" fromto="0 0 0 -0.000965 -0.0227 -0.00161" />
              <site name="tracking[tarsus_T1_right]" pos="0 0 0" size="0.005" group="0" rgba="0 1 0 1" />
              <body name="tarsus2_T1_right" pos="-0.000965 -0.0227 -0.00161">
                <geom name="tarsus2_T1_right" pos="0.000428355 -0.00758294 -0.000280125" type="capsule" size="0.00369573 0.00398953" quat="0.528967 -0.777951 -0.298981 -0.15999" />
                <geom name="tarsus2_T1_right_collision" class="collision" size="0.00159" fromto="0 0 0 0.000143 -0.0136 -0.00168" />
                <body name="tarsus3_T1_right" pos="0.000143 -0.0136 -0.00168">
                  <geom name="tarsus3_T1_right" pos="0.000413493 -0.00522729 0.000575659" type="capsule" size="0.00273365 0.00285726" quat="-0.528967 0.777951 0.298981 0.15999" />
                  <geom name="tarsus3_T1_right_collision" class="collision" size="0.00149" fromto="0 0 0 0.000437 -0.00899 -0.00063" />
                  <body name="tarsus4_T1_right" pos="0.000437 -0.00899 -0.00063">
                    <geom name="tarsus4_T1_right" pos="0.000522504 -0.00467082 -8.55839e-05" type="capsule" size="0.00228095 0.0024688" quat="0.528967 -0.777951 -0.298981 -0.15999" />
                    <geom name="tarsus4_T1_right_collision" class="collision" size="0.00148" fromto="0 0 0 0.000765 -0.00899 0.000134" />
                    <body name="claw_T1_right" pos="0.000765 -0.00899 0.000134">
                      <geom name="tarsal_claw_T1_right" material="brown" pos="0.000996252 -0.00583564 -0.00130085" type="capsule" size="0.00422871 0.00228663" quat="-0.528967 0.777951 0.298981 0.15999" />
                      <geom name="tarsal_claw_T1_right_collision" class="adhesion-collision" type="capsule" size="0.00199" fromto="0 0 0 0.000765 -0.00899 0.000134" />
                      <site name="claw_T1_right" class="adhesion-collision" size="0.00219" fromto="0 0 0 0.000765 -0.00899 0.000134" />
                      <site name="tracking[claw_T1_right]" pos="0 0.005 0" size="0.005" group="0" rgba="0 1 0 1" />
                    </body>
                  </body>
                </body>
              </body>
            </body>
          </body>
        </body>
      </body>
      <body name="coxa_T2_left" childclass="leg" pos="-0.0144 0.0241 -0.0425" quat="-0.371 0.917 -0.126 -0.0722">
        <joint name="coxa_flexion_T2_left" class="flexion_coxa_T2" />
        <joint name="coxa_twist_T2_left" class="twist_coxa_T2" />
        <geom name="coxa_T2_left" pos="0.0015033 0.0150607 -0.000523359" type="capsule" size="0.00801424 0.00727658" quat="-0.638897 -0.464659 -0.461154 0.404029" />
        <geom name="coxa_T2_left_collision" class="collision" type="ellipsoid" size="0.00788 0.007 0.0149" pos="0.000349 0.0143 -0.00216" quat="0.707 -0.707 0 0" />
        <site name="tracking[coxa_T2_left]" pos="0 0 0" size="0.005" group="0" rgba="0 1 0 1" />
        <body name="femur_T2_left" pos="0 0.0281 0" quat="0 0 0.128 0.992">
          <joint name="femur_twist_T2_left" class="twist_femur_T2" />
          <joint name="femur_T2_left" class="extend_femur_T2" />
          <site name="tracking[femur_T2_left]" pos="0 0 0" size="0.005" group="0" rgba="0 1 0 1" />
          <geom name="femur_T2_left" pos="-0.001005 0.0409271 0.00268603" type="capsule" size="0.00644685 0.0373105" quat="0.668213 -0.6907 -0.201865 -0.18888" />
          <geom name="femur_T2_left_collision" class="collision" size="0.00469" fromto="0 0.00263 0.00438 0 0.0789 0" />
          <body name="tibia_T2_left" pos="0 0.083 0" quat="0.107 0.0834 0.656 -0.742">
            <joint name="tibia_T2_left" class="extend_tibia_T2" />
            <geom name="tibia_T2_left" pos="-0.000150909 -0.0343851 -0.000358559" type="capsule" size="0.00444673 0.0303599" quat="-0.113117 0.106976 0.715191 0.681368" />
            <geom name="tibia_T2_left_collision" class="collision" size="0.00352" fromto="0 0 0 0 -0.0668 0.00175" />
            <site name="tracking[tibia_T2_left]" pos="0 0 0" size="0.005" group="0" rgba="0 1 0 1" />
            <body name="tarsus_T2_left" pos="0 -0.0668 0.00175" quat="-0.148 0.978 -0.0216 -0.143">
              <joint name="tarsus_T2_left" class="extend_tarsus_T2" />
              <geom name="tarsus_T2_left" pos="-8.17861e-06 0.0172988 0.000215126" type="capsule" size="0.00269716 0.0156399" quat="-0.0146065 0.0195705 0.694017 0.719544" />
              <geom name="tarsus_T2_left_collision" class="collision" size="0.00208" fromto="0 0 0 0.000471 0.0342 0.00136" />
              <site name="tracking[tarsus_T2_left]" pos="0 0 0" size="0.005" group="0" rgba="0 1 0 1" />
              <body name="tarsus2_T2_left" pos="0.000471 0.0342 0.00136">
                <geom name="tarsus2_T2_left" pos="-1.73726e-06 0.00913434 -3.25718e-06" type="capsule" size="0.00302112 0.00694061" quat="0.078802 0.0479958 -0.694435 -0.713615" />
                <geom name="tarsus2_T2_left_collision" class="collision" size="0.00162" fromto="0 0 0 2.42e-05 0.0178 0.000203" />
                <body name="tarsus3_T2_left" pos="2.42e-05 0.0178 0.000203">
                  <geom name="tarsus3_T2_left" pos="-4.20934e-06 0.00538076 -0.00103914" type="ellipsoid" size="0.00213066 0.00489016 0.00454702" quat="-0.0774116 0.0502075 -0.342051 0.93514" />
                  <geom name="tarsus3_T2_left_collision" class="collision" size="0.00149" fromto="0 0 0 -3.11e-05 0.00991 0.000292" />
                  <body name="tarsus4_T2_left" pos="-3.11e-05 0.00991 0.000292">
                    <geom name="tarsus4_T2_left" pos="0.000212141 0.00476284 -0.000860885" type="ellipsoid" size="0.00184751 0.00391927 0.00393788" quat="0.0774116 -0.0502075 0.342051 -0.93514" />
                    <geom name="tarsus4_T2_left_collision" class="collision" size="0.00146" fromto="0 0 0 3.6e-05 0.00991 -0.000254" />
                    <body name="claw_T2_left" pos="3.6e-05 0.00991 -0.000254">
                      <geom name="tarsal_claw_T2_left" material="brown" pos="0.00105004 0.00570629 -3.11262e-05" type="capsule" size="0.00443138 0.00175975" quat="-0.0192362 0.0902404 -0.903111 0.419377" />
                      <geom name="tarsal_claw_T2_left_collision" class="adhesion-collision" type="capsule" size="0.002" fromto="0 0 0 3.6e-05 0.00991 -0.000254" />
                      <site name="claw_T2_left" class="adhesion-collision" size="0.0022" fromto="0 0 0 3.6e-05 0.00991 -0.000254" />
                      <site name="tracking[claw_T2_left]" pos="0 0.005 0" size="0.005" group="0" rgba="0 1 0 1" />
                    </body>
                  </body>
                </body>
              </body>
            </body>
          </body>
        </body>
      </body>
      <body name="coxa_T2_right" childclass="leg" pos="-0.0144 -0.0241 -0.0425" quat="0.126 -0.0709 -0.374 -0.916">
        <joint name="coxa_flexion_T2_right" class="flexion_coxa_T2" />
        <joint name="coxa_twist_T2_right" class="twist_coxa_T2" />
        <geom name="coxa_T2_right" pos="-0.00142502 -0.0150621 0.000313839" type="capsule" size="0.00801424 0.00727658" quat="-0.404832 -0.459614 0.462593 -0.640994" />
        <geom name="coxa_T2_right_collision" class="collision" type="ellipsoid" size="0.00788 0.007 0.0149" pos="-0.000335 -0.0143 0.00206" quat="0.707 0.707 0 0" />
        <site name="tracking[coxa_T2_right]" pos="0 0 0" size="0.005" group="0" rgba="0 1 0 1" />
        <body name="femur_T2_right" pos="0 -0.0282 0" quat="0 0 0.134 0.991">
          <joint name="femur_twist_T2_right" class="twist_femur_T2" />
          <joint name="femur_T2_right" class="extend_femur_T2" />
          <geom name="femur_T2_right" pos="0.00103509 -0.0408955 -0.00236317" type="capsule" size="0.00644594 0.0373115" quat="-0.186774 0.202597 -0.693423 -0.665759" />
          <geom name="femur_T2_right_collision" class="collision" size="0.00469" fromto="0 -0.00263 -0.00438 0 -0.0798 0" />
          <site name="tracking[femur_T2_right]" pos="0 0 0" size="0.005" group="0" rgba="0 1 0 1" />
          <body name="tibia_T2_right" pos="0 -0.084 0" quat="0.0902 0.103 0.659 -0.739">
            <joint name="tibia_T2_right" class="extend_tibia_T2" />
            <geom name="tibia_T2_right" pos="-0.000103461 0.0338353 -0.000743129" type="capsule" size="0.0044463 0.0303605" quat="-0.715035 -0.687356 -0.0927806 0.0875114" />
            <geom name="tibia_T2_right_collision" class="collision" size="0.00353" fromto="0 0 0 0 0.0665 -0.00175" />
            <site name="tracking[tibia_T2_right]" pos="0 0 0" size="0.005" group="0" rgba="0 1 0 1" />
            <body name="tarsus_T2_right" pos="0 0.0665 -0.00175" quat="0.15 -0.982 0.0172 0.113">
              <joint name="tarsus_T2_right" class="extend_tarsus_T2" />
              <geom name="tarsus_T2_right" pos="5.69099e-06 -0.0171039 0.000352446" type="capsule" size="0.00269717 0.0156399" quat="-0.721281 0.692296 -0.0173448 -0.0133781" />
              <geom name="tarsus_T2_right_collision" class="collision" size="0.00208" fromto="0 0 0 -0.000367 -0.0339 -0.00103" />
              <site name="tracking[tarsus_T2_right]" pos="0 0 0" size="0.005" group="0" rgba="0 1 0 1" />
              <body name="tarsus2_T2_right" pos="-0.000367 -0.0339 -0.00103">
                <geom name="tarsus2_T2_right" pos="8.44848e-06 -0.00923444 0.000442751" type="capsule" size="0.00302117 0.00694056" quat="0.715175 -0.69283 -0.0502663 0.0773563" />
                <geom name="tarsus2_T2_right_collision" class="collision" size="0.00162" fromto="0 0 0 1.72e-05 -0.0177 -0.000553" />
                <body name="tarsus3_T2_right" pos="1.72e-05 -0.0177 -0.000553">
                  <geom name="tarsus3_T2_right" pos="-7.51769e-05 -0.00588121 0.00040906" type="ellipsoid" size="0.00213075 0.00489033 0.00454674" quat="-0.344138 0.934376 0.0788317 -0.0479193" />
                  <geom name="tarsus3_T2_right_collision" class="collision" size="0.00149" fromto="0 0 0 5.07e-05 -0.00988 -0.000293" />
                  <body name="tarsus4_T2_right" pos="5.07e-05 -0.00988 -0.000293">
                    <geom name="tarsus4_T2_right" pos="-0.000181731 -0.00526226 0.00118362" type="ellipsoid" size="0.0018476 0.00391947 0.0039376" quat="0.344138 -0.934376 -0.0788317 0.0479193" />
                    <geom name="tarsus4_T2_right_collision" class="collision" size="0.00146" fromto="0 0 0 -9.66e-05 -0.00988 0.000252" />
                    <body name="claw_T2_right" pos="-9.66e-05 -0.00988 0.000252">
                      <geom name="tarsal_claw_T2_right" material="brown" pos="-0.00100491 -0.00620247 -0.000705426" type="capsule" size="0.00443099 0.0017604" quat="0.417361 0.904046 0.0896265 0.0218584" />
                      <geom name="tarsal_claw_T2_right_collision" class="adhesion-collision" type="capsule" size="0.002" fromto="0 0 0 -9.66e-05 -0.00988 0.000252" />
                      <site name="claw_T2_right" class="adhesion-collision" size="0.0022" fromto="0 0 0 -9.66e-05 -0.00988 0.000252" />
                      <site name="tracking[claw_T2_right]" pos="0 0.005 0" size="0.005" group="0" rgba="0 1 0 1" />
                    </body>
                  </body>
                </body>
              </body>
            </body>
          </body>
        </body>
      </body>
      <body name="coxa_T3_left" childclass="leg" pos="-0.0377 0.0192 -0.0402" quat="0.681 -0.529 -0.0882 0.498">
        <joint name="coxa_flexion_T3_left" class="flexion_coxa_T3" />
        <joint name="coxa_twist_T3_left" class="twist_coxa_T3" />
        <geom name="coxa_T3_left" pos="-0.00225878 0.0138035 -0.0055289" type="capsule" size="0.00925032 0.00573129" quat="0.383739 0.0590956 0.510237 -0.767405" />
        <geom name="coxa_T3_left_collision" class="collision" type="ellipsoid" size="0.007 0.00875 0.0166" pos="-0.00348 0.0116 -0.00687" quat="0.603 -0.786 -0.135 0" />
        <site name="tracking[coxa_T3_left]" pos="0 0 0" size="0.005" group="0" rgba="0 1 0 1" />
        <body name="femur_T3_left" pos="-0.00398 0.0232 -0.00668" quat="0 0 -0.668 -0.744">
          <joint name="femur_twist_T3_left" class="twist_femur_T3" />
          <joint name="femur_T3_left" class="extend_femur_T3" />
          <geom name="femur_T3_left" pos="-0.00250665 0.0376055 0.00156746" type="capsule" size="0.00797497 0.0354335" quat="0.670499 -0.704525 -0.178072 -0.149554" />
          <geom name="femur_T3_left_collision" class="collision" size="0.00544" fromto="-0.00263 0.00263 0.00438 -0.00263 0.0766 1.52e-07" />
          <site name="tracking[femur_T3_left]" pos="0 0 0" size="0.005" group="0" rgba="0 1 0 1" />
          <body name="tibia_T3_left" pos="0 0.0779 1.6e-07" quat="-0.117 -0.104 -0.711 0.685">
            <joint name="tibia_T3_left" class="extend_tibia_T3" />
            <geom name="tibia_T3_left" pos="-0.000131536 -0.0364342 -0.00134745" type="capsule" size="0.00537691 0.0314036" quat="0.127755 -0.11138 -0.712807 -0.680573" />
            <geom name="tibia_T3_left_collision" class="collision" size="0.00365" fromto="0 -0.003 -0.005 0 -0.0715 0.00175" />
            <site name="tracking[tibia_T3_left]" pos="0 0 0" size="0.005" group="0" rgba="0 1 0 1" />
            <body name="tarsus_T3_left" pos="0 -0.0715 0.00175" quat="-0.23 0.963 -0.033 -0.138">
              <joint name="tarsus_T3_left" class="extend_tarsus_T3" />
              <geom name="tarsus_T3_left" pos="6.36662e-05 0.016825 0.000825405" type="capsule" size="0.00345418 0.0153137" quat="-0.104142 0.100234 -0.685124 -0.713942" />
              <geom name="tarsus_T3_left_collision" class="collision" size="0.00234" fromto="0 0 0 0.00027 0.0337 0.00102" />
              <site name="tracking[tarsus_T3_left]" pos="0 0 0" size="0.005" group="0" rgba="0 1 0 1" />
              <body name="tarsus2_T3_left" pos="0.00027 0.0337 0.00102">
                <geom name="tarsus2_T3_left" pos="-0.000176763 0.00961818 0.00135869" type="capsule" size="0.00168317 0.00965405" quat="0.103637 -0.0978009 0.681781 0.717544" />
                <geom name="tarsus2_T3_left_collision" class="collision" size="0.00168" fromto="0 0 0 -7.97e-05 0.0197 0.00158" />
                <body name="tarsus3_T3_left" pos="-7.97e-05 0.0197 0.00158">
                  <geom name="tarsus3_T3_left" pos="0.000110867 0.00543305 -0.000546486" type="sphere" size="0.0045838" />
                  <geom name="tarsus3_T3_left_collision" class="collision" size="0.00145" fromto="0 0 0 8e-05 0.0111 -2.78e-05" />
                  <body name="tarsus4_T3_left" pos="8e-05 0.0111 -2.78e-05">
                    <geom name="tarsus4_T3_left" pos="9.80962e-05 0.0047176 -0.000987733" type="sphere" size="0.00401168" />
                    <geom name="tarsus4_T3_left_collision" class="collision" size="0.00145" fromto="0 0 0 0.000222 0.0111 -0.00108" />
                    <body name="claw_T3_left" pos="0.000222 0.0111 -0.00108">
                      <geom name="tarsal_claw_T3_left" material="brown" pos="0.000443392 0.00609254 0.000140847" type="capsule" size="0.00504623 0.00165156" quat="-0.524104 0.484496 -0.169043 -0.679708" />
                      <geom name="tarsal_claw_T3_left_collision" class="adhesion-collision" type="capsule" size="0.0019" fromto="0 0 0 0.000222 0.0111 -0.00108" />
                      <site name="claw_T3_left" class="adhesion-collision" size="0.00209" fromto="0 0 0 0.000222 0.0111 -0.00108" />
                      <site name="tracking[claw_T3_left]" pos="0 0.005 0" size="0.005" group="0" rgba="0 1 0 1" />
                    </body>
                  </body>
                </body>
              </body>
            </body>
          </body>
        </body>
      </body>
      <body name="coxa_T3_right" childclass="leg" pos="-0.0377 -0.0192 -0.0402" quat="-0.0854 -0.505 -0.673 -0.534">
        <joint name="coxa_flexion_T3_right" class="flexion_coxa_T3" />
        <joint name="coxa_twist_T3_right" class="twist_coxa_T3" />
        <geom name="coxa_T3_right" pos="0.00214477 -0.0138905 0.00544315" type="capsule" size="0.00925032 0.0057313" quat="0.0666874 -0.375181 0.768576 0.513891" />
        <geom name="coxa_T3_right_collision" class="collision" type="ellipsoid" size="0.007 0.00875 0.0166" pos="0.00338 -0.0117 0.00678" quat="0.797 0.596 0.0983 0" />
        <site name="tracking[coxa_T3_right]" pos="0 0 0" size="0.005" group="0" rgba="0 1 0 1" />
        <body name="femur_T3_right" pos="0.00383 -0.0232 0.0066" quat="0 0 0.661 0.751">
          <joint name="femur_twist_T3_right" class="twist_femur_T3" />
          <joint name="femur_T3_right" class="extend_femur_T3" />
          <geom name="femur_T3_right" pos="0.00271217 -0.0377012 -0.00168473" type="capsule" size="0.00797497 0.0354334" quat="0.157538 -0.183546 0.700687 0.671215" />
          <geom name="femur_T3_right_collision" class="collision" size="0.00544" fromto="0.00263 -0.00263 -0.00438 0.00263 -0.0758 1.87e-07" />
          <site name="tracking[femur_T3_right]" pos="0 0 0" size="0.005" group="0" rgba="0 1 0 1" />
          <body name="tibia_T3_right" pos="0 -0.077 1.96e-07" quat="-0.121 -0.111 -0.708 0.686">
            <joint name="tibia_T3_right" class="extend_tibia_T3" />
            <geom name="tibia_T3_right" pos="0.000127308 0.0371135 0.00234218" type="capsule" size="0.0053747 0.0314059" quat="-0.110252 -0.128932 0.675258 -0.717808" />
            <geom name="tibia_T3_right_collision" class="collision" size="0.00365" fromto="0 0.003 0.005 0 0.0721 -0.00175" />
            <site name="tracking[tibia_T3_right]" pos="0 0 0" size="0.005" group="0" rgba="0 1 0 1" />
            <body name="tarsus_T3_right" pos="0 0.0721 -0.00175" quat="0.223 -0.965 0.0313 0.136">
              <joint name="tarsus_T3_right" class="extend_tarsus_T3" />
              <geom name="tarsus_T3_right" pos="-0.000626102 -0.0168471 -0.000796384" type="capsule" size="0.00345415 0.0153138" quat="-0.101392 -0.106043 -0.713487 0.685136" />
              <geom name="tarsus_T3_right_collision" class="collision" size="0.00234" fromto="0 0 0 -0.00073 -0.0338 -0.00122" />
              <site name="tracking[tarsus_T3_right]" pos="0 0 0" size="0.005" group="0" rgba="0 1 0 1" />
              <body name="tarsus2_T3_right" pos="-0.00073 -0.0338 -0.00122">
                <geom name="tarsus2_T3_right" pos="3.54713e-05 -0.00964064 -0.000339697" type="capsule" size="0.00168318 0.00965407" quat="0.0988319 0.105577 0.717216 -0.68168" />
                <geom name="tarsus2_T3_right_collision" class="collision" size="0.00168" fromto="0 0 0 0.000185 -0.0197 -0.00157" />
                <body name="tarsus3_T3_right" pos="0.000185 -0.0197 -0.00157">
                  <geom name="tarsus3_T3_right" pos="-0.000385205 -0.00545552 0.000564768" type="sphere" size="0.00458119" />
                  <geom name="tarsus3_T3_right_collision" class="collision" size="0.00145" fromto="0 0 0 1.98e-05 -0.011 1.95e-05" />
                  <body name="tarsus4_T3_right" pos="1.98e-05 -0.011 1.95e-05">
                    <geom name="tarsus4_T3_right" pos="-0.000490798 -0.00474006 0.00100283" type="sphere" size="0.00401283" />
                    <geom name="tarsus4_T3_right_collision" class="collision" size="0.00145" fromto="0 0 0 4.3e-05 -0.011 0.00125" />
                    <body name="claw_T3_right" pos="4.3e-05 -0.011 0.00125">
                      <geom name="tarsal_claw_T3_right" material="brown" pos="-0.00111539 -0.00611487 -0.00013312" type="capsule" size="0.0050418 0.00165757" quat="0.168339 0.678309 -0.524823 0.485921" />
                      <geom name="tarsal_claw_T3_right_collision" class="adhesion-collision" type="capsule" size="0.0019" fromto="0 0 0 4.3e-05 -0.011 0.00125" />
                      <site name="claw_T3_right" class="adhesion-collision" size="0.00209" fromto="0 0 0 4.3e-05 -0.011 0.00125" />
                      <site name="tracking[claw_T3_right]" pos="0 0.005 0" size="0.005" group="0" rgba="0 1 0 1" />
                    </body>
                  </body>
                </body>
              </body>
            </body>
          </body>
        </body>
      </body>
    </body>
    <camera name="hero" pos="0.271 0.27 -0.044" xyaxes="-0.641 0.767 0 -0.045 -0.037 0.998" />
  </worldbody>
  <contact>
    <exclude name="abdomen_abdomen_3" body1="abdomen" body2="abdomen_3" />
    <exclude name="abdomen_2_abdomen_4" body1="abdomen_2" body2="abdomen_4" />
    <exclude name="abdomen_3_abdomen_5" body1="abdomen_3" body2="abdomen_5" />
    <exclude name="abdomen_4_abdomen_6" body1="abdomen_4" body2="abdomen_6" />
    <exclude name="abdomen_5_abdomen_7" body1="abdomen_5" body2="abdomen_7" />
    <exclude name="wing_left_abdomen" body1="wing_left" body2="abdomen" />
    <exclude name="wing_left_abdomen_2" body1="wing_left" body2="abdomen_2" />
    <exclude name="wing_left_abdomen_3" body1="wing_left" body2="abdomen_3" />
    <exclude name="wing_right_abdomen" body1="wing_right" body2="abdomen" />
    <exclude name="wing_right_abdomen_2" body1="wing_right" body2="abdomen_2" />
    <exclude name="wing_right_abdomen_3" body1="wing_right" body2="abdomen_3" />
    <exclude name="wing_left_wing_right" body1="wing_left" body2="wing_right" />
    <exclude name="thorax_coxa_T1_left" body1="thorax" body2="coxa_T1_left" />
    <exclude name="thorax_coxa_T1_right" body1="thorax" body2="coxa_T1_right" />
    <exclude name="thorax_coxa_T2_left" body1="thorax" body2="coxa_T2_left" />
    <exclude name="thorax_coxa_T2_right" body1="thorax" body2="coxa_T2_right" />
    <exclude name="thorax_coxa_T3_left" body1="thorax" body2="coxa_T3_left" />
    <exclude name="thorax_coxa_T3_right" body1="thorax" body2="coxa_T3_right" />
    <exclude name="coxa_T1_left_coxa_T1_right" body1="coxa_T1_left" body2="coxa_T1_right" />
    <exclude name="coxa_T1_left_femur_T1_right" body1="coxa_T1_left" body2="femur_T1_right" />
    <exclude name="femur_T1_left_coxa_T1_right" body1="femur_T1_left" body2="coxa_T1_right" />
    <exclude name="femur_T1_left_femur_T1_right" body1="femur_T1_left" body2="femur_T1_right" />
    <exclude name="coxa_T2_left_coxa_T2_right" body1="coxa_T2_left" body2="coxa_T2_right" />
    <exclude name="coxa_T2_left_femur_T2_right" body1="coxa_T2_left" body2="femur_T2_right" />
    <exclude name="femur_T2_left_coxa_T2_right" body1="femur_T2_left" body2="coxa_T2_right" />
    <exclude name="femur_T2_left_femur_T2_right" body1="femur_T2_left" body2="femur_T2_right" />
    <exclude name="coxa_T3_left_coxa_T3_right" body1="coxa_T3_left" body2="coxa_T3_right" />
    <exclude name="coxa_T3_left_femur_T3_right" body1="coxa_T3_left" body2="femur_T3_right" />
    <exclude name="femur_T3_left_coxa_T3_right" body1="femur_T3_left" body2="coxa_T3_right" />
    <exclude name="femur_T3_left_femur_T3_right" body1="femur_T3_left" body2="femur_T3_right" />
    <exclude name="rostrum_labrum_left" body1="rostrum" body2="labrum_left" />
    <exclude name="rostrum_labrum_right" body1="rostrum" body2="labrum_right" />
  </contact>
  <actuator>
    <motor name="coxa_flexion_T1_left" class="flexion_coxa_T1" joint="coxa_flexion_T1_left" />
    <motor name="coxa_twist_T1_left" class="twist_coxa_T1" joint="coxa_twist_T1_left" />
    <motor name="femur_T1_left" class="extend_femur_T1" joint="femur_T1_left" />
    <motor name="femur_twist_T1_left" class="twist_femur" joint="femur_twist_T1_left" />
    <motor name="tibia_T1_left" class="extend_tibia" joint="tibia_T1_left" />
    <motor name="tarsus_T1_left" class="extend_tarsus_T1" joint="tarsus_T1_left" />
    <motor name="coxa_flexion_T1_right" class="flexion_coxa_T1" joint="coxa_flexion_T1_right" />
    <motor name="coxa_twist_T1_right" class="twist_coxa_T1" joint="coxa_twist_T1_right" />
    <motor name="femur_T1_right" class="extend_femur_T1" joint="femur_T1_right" />
    <motor name="femur_twist_T1_right" class="twist_femur" joint="femur_twist_T1_right" />
    <motor name="tibia_T1_right" class="extend_tibia" joint="tibia_T1_right" />
    <motor name="tarsus_T1_right" class="extend_tarsus_T1" joint="tarsus_T1_right" />
    <motor name="coxa_flexion_T2_left" class="flexion_coxa_T2" joint="coxa_flexion_T2_left" />
    <motor name="coxa_twist_T2_left" class="twist_coxa_T2" joint="coxa_twist_T2_left" />
    <motor name="femur_T2_left" class="extend_femur_T2" joint="femur_T2_left" />
    <motor name="femur_twist_T2_left" class="twist_femur_T2" joint="femur_twist_T2_left" />
    <motor name="tibia_T2_left" class="extend_tibia_T2" joint="tibia_T2_left" />
    <motor name="tarsus_T2_left" class="extend_tarsus_T2" joint="tarsus_T2_left" />
    <motor name="coxa_flexion_T2_right" class="flexion_coxa_T2" joint="coxa_flexion_T2_right" />
    <motor name="coxa_twist_T2_right" class="twist_coxa_T2" joint="coxa_twist_T2_right" />
    <motor name="femur_T2_right" class="extend_femur_T2" joint="femur_T2_right" />
    <motor name="femur_twist_T2_right" class="twist_femur_T2" joint="femur_twist_T2_right" />
    <motor name="tibia_T2_right" class="extend_tibia_T2" joint="tibia_T2_right" />
    <motor name="tarsus_T2_right" class="extend_tarsus_T2" joint="tarsus_T2_right" />
    <motor name="coxa_flexion_T3_left" class="flexion_coxa_T3" joint="coxa_flexion_T3_left" />
    <motor name="coxa_twist_T3_left" class="twist_coxa_T3" joint="coxa_twist_T3_left" />
    <motor name="femur_T3_left" class="extend_femur_T3" joint="femur_T3_left" />
    <motor name="femur_twist_T3_left" class="twist_femur_T3" joint="femur_twist_T3_left" />
    <motor name="tibia_T3_left" class="extend_tibia_T3" joint="tibia_T3_left" />
    <motor name="tarsus_T3_left" class="extend_tarsus_T3" joint="tarsus_T3_left" />
    <motor name="coxa_flexion_T3_right" class="flexion_coxa_T3" joint="coxa_flexion_T3_right" />
    <motor name="coxa_twist_T3_right" class="twist_coxa_T3" joint="coxa_twist_T3_right" />
    <motor name="femur_T3_right" class="extend_femur_T3" joint="femur_T3_right" />
    <motor name="femur_twist_T3_right" class="twist_femur_T3" joint="femur_twist_T3_right" />
    <motor name="tibia_T3_right" class="extend_tibia_T3" joint="tibia_T3_right" />
    <motor name="tarsus_T3_right" class="extend_tarsus_T3" joint="tarsus_T3_right" />
  </actuator>
</mujoco>